{
 "cells": [
  {
   "cell_type": "code",
   "execution_count": 1,
   "metadata": {
    "scrolled": true
   },
   "outputs": [],
   "source": [
    "# Imports\n",
    "import os\n",
    "import matplotlib.pyplot as plt\n",
    "from PIL import Image\n",
    "import math\n"
   ]
  },
  {
   "cell_type": "code",
   "execution_count": 2,
   "metadata": {},
   "outputs": [],
   "source": [
    "# Imports\n",
    "from tensorflow.keras.models import Sequential\n",
    "from tensorflow.keras.layers import Dense, Flatten, Conv2D\n",
    "from tensorflow.keras.losses import sparse_categorical_crossentropy\n",
    "from tensorflow.keras.optimizers import Adam\n",
    "from tensorflow.keras.preprocessing.image import ImageDataGenerator"
   ]
  },
  {
   "cell_type": "code",
   "execution_count": 4,
   "metadata": {},
   "outputs": [
    {
     "ename": "AttributeError",
     "evalue": "module 'tensorflow._api.v1.config' has no attribute 'list_physical_devices'",
     "output_type": "error",
     "traceback": [
      "\u001b[0;31m---------------------------------------------------------------------------\u001b[0m",
      "\u001b[0;31mAttributeError\u001b[0m                            Traceback (most recent call last)",
      "\u001b[0;32m<ipython-input-4-817240faa0fb>\u001b[0m in \u001b[0;36m<module>\u001b[0;34m\u001b[0m\n\u001b[1;32m      1\u001b[0m \u001b[0;32mimport\u001b[0m \u001b[0mtensorflow\u001b[0m \u001b[0;32mas\u001b[0m \u001b[0mtf\u001b[0m\u001b[0;34m\u001b[0m\u001b[0;34m\u001b[0m\u001b[0m\n\u001b[0;32m----> 2\u001b[0;31m \u001b[0mtf\u001b[0m\u001b[0;34m.\u001b[0m\u001b[0mconfig\u001b[0m\u001b[0;34m.\u001b[0m\u001b[0mlist_physical_devices\u001b[0m\u001b[0;34m(\u001b[0m\u001b[0;34m'GPU'\u001b[0m\u001b[0;34m)\u001b[0m\u001b[0;34m\u001b[0m\u001b[0;34m\u001b[0m\u001b[0m\n\u001b[0m",
      "\u001b[0;32m/usr/lib/python3/dist-packages/tensorflow_core/python/util/module_wrapper.py\u001b[0m in \u001b[0;36m__getattr__\u001b[0;34m(self, name)\u001b[0m\n\u001b[1;32m    191\u001b[0m   \u001b[0;32mdef\u001b[0m \u001b[0m__getattr__\u001b[0m\u001b[0;34m(\u001b[0m\u001b[0mself\u001b[0m\u001b[0;34m,\u001b[0m \u001b[0mname\u001b[0m\u001b[0;34m)\u001b[0m\u001b[0;34m:\u001b[0m\u001b[0;34m\u001b[0m\u001b[0;34m\u001b[0m\u001b[0m\n\u001b[1;32m    192\u001b[0m     \u001b[0;32mtry\u001b[0m\u001b[0;34m:\u001b[0m\u001b[0;34m\u001b[0m\u001b[0;34m\u001b[0m\u001b[0m\n\u001b[0;32m--> 193\u001b[0;31m       \u001b[0mattr\u001b[0m \u001b[0;34m=\u001b[0m \u001b[0mgetattr\u001b[0m\u001b[0;34m(\u001b[0m\u001b[0mself\u001b[0m\u001b[0;34m.\u001b[0m\u001b[0m_tfmw_wrapped_module\u001b[0m\u001b[0;34m,\u001b[0m \u001b[0mname\u001b[0m\u001b[0;34m)\u001b[0m\u001b[0;34m\u001b[0m\u001b[0;34m\u001b[0m\u001b[0m\n\u001b[0m\u001b[1;32m    194\u001b[0m     \u001b[0;32mexcept\u001b[0m \u001b[0mAttributeError\u001b[0m\u001b[0;34m:\u001b[0m\u001b[0;34m\u001b[0m\u001b[0;34m\u001b[0m\u001b[0m\n\u001b[1;32m    195\u001b[0m       \u001b[0;32mif\u001b[0m \u001b[0;32mnot\u001b[0m \u001b[0mself\u001b[0m\u001b[0;34m.\u001b[0m\u001b[0m_tfmw_public_apis\u001b[0m\u001b[0;34m:\u001b[0m\u001b[0;34m\u001b[0m\u001b[0;34m\u001b[0m\u001b[0m\n",
      "\u001b[0;31mAttributeError\u001b[0m: module 'tensorflow._api.v1.config' has no attribute 'list_physical_devices'"
     ]
    }
   ],
   "source": [
    "import tensorflow as tf\n",
    "tf.config.list_physical_devices('GPU')"
   ]
  },
  {
   "cell_type": "code",
   "execution_count": 17,
   "metadata": {},
   "outputs": [
    {
     "name": "stdout",
     "output_type": "stream",
     "text": [
      "1.15.3\n"
     ]
    }
   ],
   "source": [
    "print(tf.__version__)"
   ]
  },
  {
   "cell_type": "code",
   "execution_count": 11,
   "metadata": {},
   "outputs": [],
   "source": [
    "# Data configuration\n",
    "training_set_folder = './Training_smaller'\n",
    "test_set_folder     = './Test_smaller'\n",
    "\n",
    "# Model configuration\n",
    "batch_size = 5\n",
    "img_width, img_height, img_num_channels = 25, 25, 3\n",
    "loss_function = sparse_categorical_crossentropy\n",
    "no_classes = 10\n",
    "no_epochs = 10\n",
    "optimizer = Adam()\n",
    "verbosity = 1"
   ]
  },
  {
   "cell_type": "code",
   "execution_count": 12,
   "metadata": {},
   "outputs": [
    {
     "name": "stdout",
     "output_type": "stream",
     "text": [
      "Found 1409 images belonging to 3 classes.\n"
     ]
    }
   ],
   "source": [
    "# Determine shape of the data\n",
    "input_shape = (img_width, img_height, img_num_channels)\n",
    "\n",
    "# Create a generator\n",
    "train_datagen = ImageDataGenerator(\n",
    "  rescale=1./255\n",
    ")\n",
    "train_datagen = train_datagen.flow_from_directory(\n",
    "        training_set_folder,\n",
    "        save_to_dir='./Data_generated',\n",
    "        save_format='jpeg',\n",
    "        batch_size=batch_size,\n",
    "        target_size=(25, 25),\n",
    "        class_mode='sparse')"
   ]
  },
  {
   "cell_type": "code",
   "execution_count": null,
   "metadata": {},
   "outputs": [],
   "source": [
    "train_datagen = ImageDataGenerator(rescale=1./255)\n",
    "\n",
    "train_generator = train_datagen.flow_from_directory(\n",
    "        train_data_dir,\n",
    "        target_size=(img_rows, img_cols),\n",
    "        batch_size =batch_size,\n",
    "        class_mode='categorical',\n",
    "        shuffle=True)"
   ]
  },
  {
   "cell_type": "code",
   "execution_count": 13,
   "metadata": {},
   "outputs": [
    {
     "name": "stdout",
     "output_type": "stream",
     "text": [
      "Model: \"sequential_1\"\n",
      "_________________________________________________________________\n",
      "Layer (type)                 Output Shape              Param #   \n",
      "=================================================================\n",
      "conv2d_4 (Conv2D)            (None, 21, 21, 16)        1216      \n",
      "_________________________________________________________________\n",
      "conv2d_5 (Conv2D)            (None, 17, 17, 32)        12832     \n",
      "_________________________________________________________________\n",
      "conv2d_6 (Conv2D)            (None, 13, 13, 64)        51264     \n",
      "_________________________________________________________________\n",
      "conv2d_7 (Conv2D)            (None, 9, 9, 128)         204928    \n",
      "_________________________________________________________________\n",
      "flatten_1 (Flatten)          (None, 10368)             0         \n",
      "_________________________________________________________________\n",
      "dense_2 (Dense)              (None, 16)                165904    \n",
      "_________________________________________________________________\n",
      "dense_3 (Dense)              (None, 10)                170       \n",
      "=================================================================\n",
      "Total params: 436,314\n",
      "Trainable params: 436,314\n",
      "Non-trainable params: 0\n",
      "_________________________________________________________________\n"
     ]
    }
   ],
   "source": [
    "# Create the model\n",
    "model = Sequential()\n",
    "model.add(Conv2D(16, kernel_size=(5, 5), activation='relu', input_shape=input_shape))\n",
    "model.add(Conv2D(32, kernel_size=(5, 5), activation='relu'))\n",
    "model.add(Conv2D(64, kernel_size=(5, 5), activation='relu'))\n",
    "model.add(Conv2D(128, kernel_size=(5, 5), activation='relu'))\n",
    "model.add(Flatten())\n",
    "model.add(Dense(16, activation='relu'))\n",
    "model.add(Dense(no_classes, activation='softmax'))\n",
    "\n",
    "# Display a model summary\n",
    "model.summary()"
   ]
  },
  {
   "cell_type": "code",
   "execution_count": 14,
   "metadata": {
    "scrolled": true
   },
   "outputs": [
    {
     "name": "stdout",
     "output_type": "stream",
     "text": [
      "Epoch 1/10\n"
     ]
    },
    {
     "ename": "UnknownError",
     "evalue": "2 root error(s) found.\n  (0) Unknown: Failed to get convolution algorithm. This is probably because cuDNN failed to initialize, so try looking to see if a warning log message was printed above.\n\t [[{{node conv2d_4/Conv2D}}]]\n  (1) Unknown: Failed to get convolution algorithm. This is probably because cuDNN failed to initialize, so try looking to see if a warning log message was printed above.\n\t [[{{node conv2d_4/Conv2D}}]]\n\t [[metrics_2/acc/Identity/_219]]\n0 successful operations.\n0 derived errors ignored.",
     "output_type": "error",
     "traceback": [
      "\u001b[0;31m---------------------------------------------------------------------------\u001b[0m",
      "\u001b[0;31mUnknownError\u001b[0m                              Traceback (most recent call last)",
      "\u001b[0;32m<ipython-input-14-ad02326a7a0c>\u001b[0m in \u001b[0;36m<module>\u001b[0;34m\u001b[0m\n\u001b[1;32m      8\u001b[0m         \u001b[0mtrain_datagen\u001b[0m\u001b[0;34m,\u001b[0m\u001b[0;34m\u001b[0m\u001b[0;34m\u001b[0m\u001b[0m\n\u001b[1;32m      9\u001b[0m         \u001b[0mepochs\u001b[0m\u001b[0;34m=\u001b[0m\u001b[0mno_epochs\u001b[0m\u001b[0;34m,\u001b[0m\u001b[0;34m\u001b[0m\u001b[0;34m\u001b[0m\u001b[0m\n\u001b[0;32m---> 10\u001b[0;31m         shuffle=False)\n\u001b[0m",
      "\u001b[0;32m/usr/lib/python3/dist-packages/tensorflow_core/python/keras/engine/training.py\u001b[0m in \u001b[0;36mfit\u001b[0;34m(self, x, y, batch_size, epochs, verbose, callbacks, validation_split, validation_data, shuffle, class_weight, sample_weight, initial_epoch, steps_per_epoch, validation_steps, validation_freq, max_queue_size, workers, use_multiprocessing, **kwargs)\u001b[0m\n\u001b[1;32m    725\u001b[0m         \u001b[0mmax_queue_size\u001b[0m\u001b[0;34m=\u001b[0m\u001b[0mmax_queue_size\u001b[0m\u001b[0;34m,\u001b[0m\u001b[0;34m\u001b[0m\u001b[0;34m\u001b[0m\u001b[0m\n\u001b[1;32m    726\u001b[0m         \u001b[0mworkers\u001b[0m\u001b[0;34m=\u001b[0m\u001b[0mworkers\u001b[0m\u001b[0;34m,\u001b[0m\u001b[0;34m\u001b[0m\u001b[0;34m\u001b[0m\u001b[0m\n\u001b[0;32m--> 727\u001b[0;31m         use_multiprocessing=use_multiprocessing)\n\u001b[0m\u001b[1;32m    728\u001b[0m \u001b[0;34m\u001b[0m\u001b[0m\n\u001b[1;32m    729\u001b[0m   def evaluate(self,\n",
      "\u001b[0;32m/usr/lib/python3/dist-packages/tensorflow_core/python/keras/engine/training_generator.py\u001b[0m in \u001b[0;36mfit\u001b[0;34m(self, model, x, y, batch_size, epochs, verbose, callbacks, validation_split, validation_data, shuffle, class_weight, sample_weight, initial_epoch, steps_per_epoch, validation_steps, validation_freq, max_queue_size, workers, use_multiprocessing)\u001b[0m\n\u001b[1;32m    601\u001b[0m         \u001b[0mshuffle\u001b[0m\u001b[0;34m=\u001b[0m\u001b[0mshuffle\u001b[0m\u001b[0;34m,\u001b[0m\u001b[0;34m\u001b[0m\u001b[0;34m\u001b[0m\u001b[0m\n\u001b[1;32m    602\u001b[0m         \u001b[0minitial_epoch\u001b[0m\u001b[0;34m=\u001b[0m\u001b[0minitial_epoch\u001b[0m\u001b[0;34m,\u001b[0m\u001b[0;34m\u001b[0m\u001b[0;34m\u001b[0m\u001b[0m\n\u001b[0;32m--> 603\u001b[0;31m         steps_name='steps_per_epoch')\n\u001b[0m\u001b[1;32m    604\u001b[0m \u001b[0;34m\u001b[0m\u001b[0m\n\u001b[1;32m    605\u001b[0m   def evaluate(self,\n",
      "\u001b[0;32m/usr/lib/python3/dist-packages/tensorflow_core/python/keras/engine/training_generator.py\u001b[0m in \u001b[0;36mmodel_iteration\u001b[0;34m(model, data, steps_per_epoch, epochs, verbose, callbacks, validation_data, validation_steps, validation_freq, class_weight, max_queue_size, workers, use_multiprocessing, shuffle, initial_epoch, mode, batch_size, steps_name, **kwargs)\u001b[0m\n\u001b[1;32m    263\u001b[0m \u001b[0;34m\u001b[0m\u001b[0m\n\u001b[1;32m    264\u001b[0m       \u001b[0mis_deferred\u001b[0m \u001b[0;34m=\u001b[0m \u001b[0;32mnot\u001b[0m \u001b[0mmodel\u001b[0m\u001b[0;34m.\u001b[0m\u001b[0m_is_compiled\u001b[0m\u001b[0;34m\u001b[0m\u001b[0;34m\u001b[0m\u001b[0m\n\u001b[0;32m--> 265\u001b[0;31m       \u001b[0mbatch_outs\u001b[0m \u001b[0;34m=\u001b[0m \u001b[0mbatch_function\u001b[0m\u001b[0;34m(\u001b[0m\u001b[0;34m*\u001b[0m\u001b[0mbatch_data\u001b[0m\u001b[0;34m)\u001b[0m\u001b[0;34m\u001b[0m\u001b[0;34m\u001b[0m\u001b[0m\n\u001b[0m\u001b[1;32m    266\u001b[0m       \u001b[0;32mif\u001b[0m \u001b[0;32mnot\u001b[0m \u001b[0misinstance\u001b[0m\u001b[0;34m(\u001b[0m\u001b[0mbatch_outs\u001b[0m\u001b[0;34m,\u001b[0m \u001b[0mlist\u001b[0m\u001b[0;34m)\u001b[0m\u001b[0;34m:\u001b[0m\u001b[0;34m\u001b[0m\u001b[0;34m\u001b[0m\u001b[0m\n\u001b[1;32m    267\u001b[0m         \u001b[0mbatch_outs\u001b[0m \u001b[0;34m=\u001b[0m \u001b[0;34m[\u001b[0m\u001b[0mbatch_outs\u001b[0m\u001b[0;34m]\u001b[0m\u001b[0;34m\u001b[0m\u001b[0;34m\u001b[0m\u001b[0m\n",
      "\u001b[0;32m/usr/lib/python3/dist-packages/tensorflow_core/python/keras/engine/training.py\u001b[0m in \u001b[0;36mtrain_on_batch\u001b[0;34m(self, x, y, sample_weight, class_weight, reset_metrics)\u001b[0m\n\u001b[1;32m   1015\u001b[0m       \u001b[0mself\u001b[0m\u001b[0;34m.\u001b[0m\u001b[0m_update_sample_weight_modes\u001b[0m\u001b[0;34m(\u001b[0m\u001b[0msample_weights\u001b[0m\u001b[0;34m=\u001b[0m\u001b[0msample_weights\u001b[0m\u001b[0;34m)\u001b[0m\u001b[0;34m\u001b[0m\u001b[0;34m\u001b[0m\u001b[0m\n\u001b[1;32m   1016\u001b[0m       \u001b[0mself\u001b[0m\u001b[0;34m.\u001b[0m\u001b[0m_make_train_function\u001b[0m\u001b[0;34m(\u001b[0m\u001b[0;34m)\u001b[0m\u001b[0;34m\u001b[0m\u001b[0;34m\u001b[0m\u001b[0m\n\u001b[0;32m-> 1017\u001b[0;31m       \u001b[0moutputs\u001b[0m \u001b[0;34m=\u001b[0m \u001b[0mself\u001b[0m\u001b[0;34m.\u001b[0m\u001b[0mtrain_function\u001b[0m\u001b[0;34m(\u001b[0m\u001b[0mins\u001b[0m\u001b[0;34m)\u001b[0m  \u001b[0;31m# pylint: disable=not-callable\u001b[0m\u001b[0;34m\u001b[0m\u001b[0;34m\u001b[0m\u001b[0m\n\u001b[0m\u001b[1;32m   1018\u001b[0m \u001b[0;34m\u001b[0m\u001b[0m\n\u001b[1;32m   1019\u001b[0m     \u001b[0;32mif\u001b[0m \u001b[0mreset_metrics\u001b[0m\u001b[0;34m:\u001b[0m\u001b[0;34m\u001b[0m\u001b[0;34m\u001b[0m\u001b[0m\n",
      "\u001b[0;32m/usr/lib/python3/dist-packages/tensorflow_core/python/keras/backend.py\u001b[0m in \u001b[0;36m__call__\u001b[0;34m(self, inputs)\u001b[0m\n\u001b[1;32m   3474\u001b[0m \u001b[0;34m\u001b[0m\u001b[0m\n\u001b[1;32m   3475\u001b[0m     fetched = self._callable_fn(*array_vals,\n\u001b[0;32m-> 3476\u001b[0;31m                                 run_metadata=self.run_metadata)\n\u001b[0m\u001b[1;32m   3477\u001b[0m     \u001b[0mself\u001b[0m\u001b[0;34m.\u001b[0m\u001b[0m_call_fetch_callbacks\u001b[0m\u001b[0;34m(\u001b[0m\u001b[0mfetched\u001b[0m\u001b[0;34m[\u001b[0m\u001b[0;34m-\u001b[0m\u001b[0mlen\u001b[0m\u001b[0;34m(\u001b[0m\u001b[0mself\u001b[0m\u001b[0;34m.\u001b[0m\u001b[0m_fetches\u001b[0m\u001b[0;34m)\u001b[0m\u001b[0;34m:\u001b[0m\u001b[0;34m]\u001b[0m\u001b[0;34m)\u001b[0m\u001b[0;34m\u001b[0m\u001b[0;34m\u001b[0m\u001b[0m\n\u001b[1;32m   3478\u001b[0m     output_structure = nest.pack_sequence_as(\n",
      "\u001b[0;32m/usr/lib/python3/dist-packages/tensorflow_core/python/client/session.py\u001b[0m in \u001b[0;36m__call__\u001b[0;34m(self, *args, **kwargs)\u001b[0m\n\u001b[1;32m   1470\u001b[0m         ret = tf_session.TF_SessionRunCallable(self._session._session,\n\u001b[1;32m   1471\u001b[0m                                                \u001b[0mself\u001b[0m\u001b[0;34m.\u001b[0m\u001b[0m_handle\u001b[0m\u001b[0;34m,\u001b[0m \u001b[0margs\u001b[0m\u001b[0;34m,\u001b[0m\u001b[0;34m\u001b[0m\u001b[0;34m\u001b[0m\u001b[0m\n\u001b[0;32m-> 1472\u001b[0;31m                                                run_metadata_ptr)\n\u001b[0m\u001b[1;32m   1473\u001b[0m         \u001b[0;32mif\u001b[0m \u001b[0mrun_metadata\u001b[0m\u001b[0;34m:\u001b[0m\u001b[0;34m\u001b[0m\u001b[0;34m\u001b[0m\u001b[0m\n\u001b[1;32m   1474\u001b[0m           \u001b[0mproto_data\u001b[0m \u001b[0;34m=\u001b[0m \u001b[0mtf_session\u001b[0m\u001b[0;34m.\u001b[0m\u001b[0mTF_GetBuffer\u001b[0m\u001b[0;34m(\u001b[0m\u001b[0mrun_metadata_ptr\u001b[0m\u001b[0;34m)\u001b[0m\u001b[0;34m\u001b[0m\u001b[0;34m\u001b[0m\u001b[0m\n",
      "\u001b[0;31mUnknownError\u001b[0m: 2 root error(s) found.\n  (0) Unknown: Failed to get convolution algorithm. This is probably because cuDNN failed to initialize, so try looking to see if a warning log message was printed above.\n\t [[{{node conv2d_4/Conv2D}}]]\n  (1) Unknown: Failed to get convolution algorithm. This is probably because cuDNN failed to initialize, so try looking to see if a warning log message was printed above.\n\t [[{{node conv2d_4/Conv2D}}]]\n\t [[metrics_2/acc/Identity/_219]]\n0 successful operations.\n0 derived errors ignored."
     ]
    }
   ],
   "source": [
    "# Compile the model\n",
    "model.compile(loss=loss_function,\n",
    "              optimizer=optimizer,\n",
    "              metrics=['accuracy'])\n",
    "\n",
    "# Start training\n",
    "model.fit(\n",
    "        train_datagen,\n",
    "        epochs=no_epochs,\n",
    "        shuffle=False)"
   ]
  },
  {
   "cell_type": "code",
   "execution_count": 10,
   "metadata": {},
   "outputs": [],
   "source": [
    "from IPython.core.interactiveshell import InteractiveShell\n",
    "\n",
    "InteractiveShell.ast_node_interactivity = \"all\""
   ]
  }
 ],
 "metadata": {
  "kernelspec": {
   "display_name": "Python 3",
   "language": "python",
   "name": "python3"
  },
  "language_info": {
   "codemirror_mode": {
    "name": "ipython",
    "version": 3
   },
   "file_extension": ".py",
   "mimetype": "text/x-python",
   "name": "python",
   "nbconvert_exporter": "python",
   "pygments_lexer": "ipython3",
   "version": "3.7.6"
  }
 },
 "nbformat": 4,
 "nbformat_minor": 4
}
